{'check_cycle': 0,
 'check_homogeneous': 1,
 'focus_ops': 'dm',
 'force_rebuild': 1,
 'init_test': 'auto',
 'log_level': 'INFO',
 'math_dir': './Neq/math',
 'max_tokens': 4096,
 'norm_goal': 0,
 'num_threads': 96,
 'oai_version': 'gpt-4o',
 'problem': 'theorem P19 {a b c d : ℝ} (ha : a > 0) (hb : b > 0) (hc : c > 0) (hd : d > 0) (h : a + b + c + d = 4) : 2 / 3 ≤ a / (b ^ 3 + 4) + b / (c ^ 3 + 4) '
            '+ c / (d ^ 3 + 4) + d / (a ^ 3 + 4) := by  sorry',
 'prover_vb': 0,
 'rank_size': 10,
 'repl_dir': './Neq/repl',
 'rewrite_length': 5,
 'rewrite_limit': 1,
 'save_dir': 'Results',
 'scale_equality': 0,
 'scale_limit': 128,
 'smt_config': '',
 'sym_rewrite': 0,
 'temperature': 0.7,
 'top_p': 0.95}
================================================== Prover Configs ==================================================
LeanLM configuration: 
oai details: gpt-4o
llm generation details: temperature=0.7, top_p=0.95, max_tokens=4096
smt config: 
initial test case: auto
save directory: Results


================================================== Iteration 0 ==================================================
Start time: 2025-03-14 10:02:09.982799
/home/argustest/tzh/NeqLIPS/LIPS/NeSyCore/llm.py:62: UserWarning: gpt-4 encounter an error The api_key client option must be set either by passing api_key to the client or by setting the OPENAI_API_KEY environment variable
  warnings.warn(f"gpt-4 encounter an error {e}")
/home/argustest/tzh/NeqLIPS/LIPS/NeSyCore/llm.py:62: UserWarning: gpt-4 encounter an error The api_key client option must be set either by passing api_key to the client or by setting the OPENAI_API_KEY environment variable
  warnings.warn(f"gpt-4 encounter an error {e}")
/home/argustest/tzh/NeqLIPS/LIPS/NeSyCore/llm.py:62: UserWarning: gpt-4 encounter an error The api_key client option must be set either by passing api_key to the client or by setting the OPENAI_API_KEY environment variable
  warnings.warn(f"gpt-4 encounter an error {e}")
/home/argustest/tzh/NeqLIPS/LIPS/NeSyCore/llm.py:62: UserWarning: gpt-4 encounter an error The api_key client option must be set either by passing api_key to the client or by setting the OPENAI_API_KEY environment variable
  warnings.warn(f"gpt-4 encounter an error {e}")
/home/argustest/tzh/NeqLIPS/LIPS/NeSyCore/llm.py:62: UserWarning: gpt-4 encounter an error The api_key client option must be set either by passing api_key to the client or by setting the OPENAI_API_KEY environment variable
  warnings.warn(f"gpt-4 encounter an error {e}")
/home/argustest/tzh/NeqLIPS/LIPS/NeSyCore/llm.py:62: UserWarning: gpt-4 encounter an error The api_key client option must be set either by passing api_key to the client or by setting the OPENAI_API_KEY environment variable
  warnings.warn(f"gpt-4 encounter an error {e}")
/home/argustest/tzh/NeqLIPS/LIPS/NeSyCore/llm.py:62: UserWarning: gpt-4 encounter an error The api_key client option must be set either by passing api_key to the client or by setting the OPENAI_API_KEY environment variable
  warnings.warn(f"gpt-4 encounter an error {e}")
/home/argustest/tzh/NeqLIPS/LIPS/NeSyCore/llm.py:62: UserWarning: gpt-4 encounter an error The api_key client option must be set either by passing api_key to the client or by setting the OPENAI_API_KEY environment variable
  warnings.warn(f"gpt-4 encounter an error {e}")
/home/argustest/tzh/NeqLIPS/LIPS/NeSyCore/llm.py:62: UserWarning: gpt-4 encounter an error The api_key client option must be set either by passing api_key to the client or by setting the OPENAI_API_KEY environment variable
  warnings.warn(f"gpt-4 encounter an error {e}")
/home/argustest/tzh/NeqLIPS/LIPS/NeSyCore/llm.py:62: UserWarning: gpt-4 encounter an error The api_key client option must be set either by passing api_key to the client or by setting the OPENAI_API_KEY environment variable
  warnings.warn(f"gpt-4 encounter an error {e}")
/home/argustest/tzh/NeqLIPS/LIPS/NeSyCore/llm.py:62: UserWarning: gpt-4 encounter an error The api_key client option must be set either by passing api_key to the client or by setting the OPENAI_API_KEY environment variable
  warnings.warn(f"gpt-4 encounter an error {e}")
/home/argustest/tzh/NeqLIPS/LIPS/NeSyCore/llm.py:62: UserWarning: gpt-4 encounter an error The api_key client option must be set either by passing api_key to the client or by setting the OPENAI_API_KEY environment variable
  warnings.warn(f"gpt-4 encounter an error {e}")
/home/argustest/tzh/NeqLIPS/LIPS/NeSyCore/llm.py:62: UserWarning: gpt-4 encounter an error The api_key client option must be set either by passing api_key to the client or by setting the OPENAI_API_KEY environment variable
  warnings.warn(f"gpt-4 encounter an error {e}")
Traceback (most recent call last):
  File "/home/argustest/tzh/NeqLIPS/prove.py", line 73, in <module>
    generate(prover, problem)
  File "/home/argustest/tzh/NeqLIPS/prove.py", line 52, in generate
    states = prover.get_state(proof_state, steps)
  File "/home/argustest/tzh/NeqLIPS/LIPS/prover.py", line 337, in get_state
    new_proof_state = self.leanio.apply(tactic, proof_state)
  File "/home/argustest/anaconda3/envs/NeqLIPS/lib/python3.10/site-packages/wrapt_timeout_decorator/wrapt_timeout_decorator.py", line 229, in wrapper
    return wrapped_with_timeout(wrap_helper)
  File "/home/argustest/anaconda3/envs/NeqLIPS/lib/python3.10/site-packages/wrapt_timeout_decorator/wrapt_timeout_decorator.py", line 236, in wrapped_with_timeout
    return wrapped_with_timeout_signals(wrap_helper)
  File "/home/argustest/anaconda3/envs/NeqLIPS/lib/python3.10/site-packages/wrapt_timeout_decorator/wrapt_timeout_decorator.py", line 244, in wrapped_with_timeout_signals
    return wrap_helper.wrapped(*wrap_helper.args, **wrap_helper.kwargs)
  File "/home/argustest/tzh/NeqLIPS/LIPS/LeanIO/env.py", line 123, in apply
    res = read_json(stdin=self.process.stdout)
  File "/home/argustest/tzh/NeqLIPS/LIPS/LeanIO/cmds.py", line 44, in read_json
    s = s + stdin.readline()
  File "/home/argustest/anaconda3/envs/NeqLIPS/lib/python3.10/site-packages/wrapt_timeout_decorator/wrap_helper.py", line 97, in new_alarm_handler
    raise_exception(self.timeout_exception, self.exception_message)
  File "/home/argustest/anaconda3/envs/NeqLIPS/lib/python3.10/site-packages/wrapt_timeout_decorator/wrap_helper.py", line 249, in raise_exception
    raise exception(exception_message)
TimeoutError: Function apply timed out after 30.0 seconds
